Workbook
Name OLE_LINK1: 'Europa y Euroasia'!#REF!

Sheet Inicio
C4: Importaciones de gas natural por áreas geográficas y países
C9: Fuente/Notas | D9: 2004-marzo 2009 | E9: Anejos de la Resolución del 15 de Julio de 2002
D10: abril 2009-actualidad | E10: Anejos de la Resolución del 15 de diciembre 2008
D11: enero 2015-actualidad | E11: Por adaptación a la legislación europea, desde enero de 2015, desaparece el concepto de contrato de tránsito de gas, tratándose en adelante como una importación y una exportación más. En consecuencia los datos de 2014 y 2015 no siempre son comparables.
E12: A partir de agosto 2021 aparecen nuevos países que anteriormente se encontraban en otras agrupaciones
E13: ^ mayor que 0
A16: Actualizado el 14-09-2026 | G16: Para más información: cores.institucional@cores.es. Tlf.: +34 91 360 09 10, o visite: www.cores.es

Sheet África
C3: =Inicio!C4 -> Importaciones de gas natural por áreas geográficas y países
A4: =Inicio!$A$16 -> Actualizado el 14-09-2026 | S4: Unidad: gigavatio hora
C5: África
A6: Año | B6: Mes | C6: Angola GNL | D6: Argelia | E6: Argelia GNL | F6: Argelia GN | G6: Camerún GNL | H6: Congo GNL | I6: Egipto GNL | J6: Guinea Ecuatorial GNL | K6: Libia GNL | L6: Mauritania GNL | M6: Mozambique GNL | N6: Nigeria | O6: Nigeria GNL | P6: Nigeria GN | Q6: Total África | R6: Total África GNL | S6: Total África GN
A7: 2004 | B7: enero | D7: 15667.722 | E7: 9155.8528 | F7: 6511.869 | I7: 0 | J7: 0 | K7: 723.8085 | N7: 4533.35 | O7: 4533.35 | P7: 0 | Q7: 20924.88 | R7: 14413.011 | S7: 6511.869
A8: 2004 | B8: febrero | D8: 14909.618 | E8: 7712.4968 | F8: 7197.1213 | I8: 0 | J8: 0 | K8: 723.7128 | N8: 3856.8568 | O8: 3518.4752 | P8: 338.38161 | Q8: 19490.188 | R8: 11954.685 | S8: 7535.5029
A9: 2004 | B9: marzo | D9: 14662.131 | E9: 6418.8038 | F9: 8243.327 | I9: 0 | J9: 0 | K9: 732.0007 | N9: 5546.4526 | O9: 5208.0997 | P9: 338.35289 | Q9: 20940.584 | R9: 12358.904 | S9: 8581.6799
A10: 2004 | B10: abril | D10: 11929.376 | E10: 6651.0921 | F10: 5278.284 | I10: 0 | J10: 0 | K10: 487.0423 | N10: 4448.7712 | O10: 4448.594 | P10: 0.17721 | Q10: 16865.19 | R10: 11586.728 | S10: 5278.4612
A11: 2004 | B11: mayo | D11: 10727.015 | E11: 5406.4592 | F11: 5320.5562 | I11: 0 | J11: 0 | K11: 971.6548 | N11: 5848.4457 | O11: 5615.6211 | P11: 232.82456 | Q11: 17547.116 | R11: 11993.735 | S11: 5553.3807
A12: 2004 | B12: junio | D12: 10148.506 | E12: 3944.8118 | F12: 6203.6943 | I12: 0 | J12: 0 | K12: 728.8337 | N12: 4875.7018 | O12: 4874.2844 | P12: 1.41738 | Q12: 15753.042 | R12: 9547.9299 | S12: 6205.1117
A13: 2004 | B13: julio | D13: 11933.316 | E13: 5221.3938 | F13: 6711.922 | I13: 0 | J13: 0 | K13: 721.9886 | N13: 4248.3623 | O13: 4248.3623 | P13: 0 | Q13: 16903.667 | R13: 10191.745 | S13: 6711.922
A14: 2004 | B14: agosto | D14: 11155.417 | E14: 5276.8823 | F14: 5878.535 | I14: 0 | J14: 0 | K14: 7.57282 | N14: 4229.1824 | O14: 4229.1824 | P14: 0 | Q14: 15392.172 | R14: 9513.6375 | S14: 5878.535
A15: 2004 | B15: septiembre | D15: 13280.247 | E15: 5971.9545 | F15: 7308.2921 | I15: 0 | J15: 0 | K15: 477.9151 | N15: 5940.881 | O15: 5940.3593 | P15: 0.52169 | Q15: 19699.043 | R15: 12390.229 | S15: 7308.8138
A16: 2004 | B16: octubre | D16: 14540.002 | E16: 6340.9898 | F16: 8199.0117 | I16: 0 | J16: 0 | K16: 731.0999 | N16: 5924.2679 | O16: 5922.8032 | P16: 1.4647 | Q16: 21195.369 | R16: 12994.893 | S16: 8200.4765
A17: 2004 | B17: noviembre | D17: 16333.855 | E17: 7176.234 | F17: 9157.6212 | I17: 0 | J17: 0 | K17: 729.5162 | N17: 4778.395 | O17: 4776.9761 | P17: 1.41886 | Q17: 21841.766 | R17: 12682.726 | S17: 9159.0401
A18: 2004 | B18: diciembre | D18: 14064.26 | E18: 5795.8041 | F18: 8268.456 | I18: 0 | J18: 0 | K18: 729.7091 | N18: 3458.211 | O18: 3456.748 | P18: 1.463 | Q18: 18252.18 | R18: 9982.2612 | S18: 8269.919
... A58: 2007 | B58: total | D58: 145741.2 | E58: 46358.962 | F58: 99382.238 | I58: 46664.441 | J58: 0 | K58: 8760.1668 | N58: 98317.485 | O58: 97957.885 | P58: 359.6 | Q58: 299483.29 | R58: 199741.45 | S58: 99741.838
A59: 2008 | B59: enero | D59: 14464.221 | E59: 4291.3704 | F59: 10172.851 | I59: 3981.7162 | K59: 727.8484 | N59: 9893.4252 | O59: 9893.4252 | P59: 0 | Q59: 29067.211 | R59: =O59+E59+I59+J59+K59 -> 18894.36 | S59: =F59+P59 -> 10172.851
A60: 2008 | B60: febrero | D60: 13975.41 | E60: 3889.3594 | F60: 10086.05 | I60: 4570.8916 | K60: 487.26292 | N60: 8194.9515 | O60: 8194.9514 | P60: 0 | Q60: 27228.516 | R60: =O60+E60+I60+J60+K60 -> 17142.465 | S60: =F60+P60 -> 10086.05
A61: 2008 | B61: marzo | D61: 14722.592 | E61: 5051.8696 | F61: 9670.7222 | I61: 3651.3101 | K61: 730.30704 | N61: 8385.711 | O61: 8385.7109 | P61: 0 | Q61: 27489.92 | R61: =O61+E61+I61+J61+K61 -> 17819.198 | S61: =F61+P61 -> 9670.7222
A62: 2008 | B62: abril | D62: 14551.938 | E62: 5567.0352 | F62: 8984.9031 | I62: 5769.993 | K62: 731.52121 | N62: 5381.503 | O62: 5381.503 | P62: 0 | Q62: 26434.955 | R62: =O62+E62+I62+J62+K62 -> 17450.052 | S62: =F62+P62 -> 8984.9031
A63: 2008 | B63: mayo | D63: 13316.268 | E63: 4671.025 | F63: 8645.2433 | I63: 3681.1958 | K63: 491.92638 | N63: 7820.5496 | O63: 7820.5496 | P63: 0 | Q63: 25309.94 | R63: =O63+E63+I63+J63+K63 -> 16664.697 | S63: =F63+P63 -> 8645.2433
A64: 2008 | B64: junio | D64: 13522.502 | E64: 4429.7052 | F64: 9092.7964 | I64: 3747.3705 | K64: 488.65575 | N64: 10359.912 | O64: 10359.912 | P64: 0 | Q64: 28118.44 | R64: =O64+E64+I64+J64+K64 -> 19025.644 | S64: =F64+P64 -> 9092.7964
A65: 2008 | B65: julio | D65: 13547.12 | E65: 4486.7896 | F65: 9060.3307 | I65: 5335.3233 | K65: 245.9952 | N65: 9109.1418 | O65: 9109.1418 | P65: 0 | Q65: 28237.581 | R65: =O65+E65+I65+J65+K65 -> 19177.25 | S65: =F65+P65 -> 9060.3307
A66: 2008 | B66: agosto | D66: 12098.784 | E66: 4175.2994 | F66: 7923.4846 | I66: 5590.6821 | N66: 5253.4051 | O66: 5253.4051 | P66: 0 | Q66: 22942.871 | R66: =O66+E66+I66+J66+K66 -> 15019.387 | S66: =F66+P66 -> 7923.4846
A67: 2008 | B67: septiembre | D67: 11946.584 | E67: 3498.0563 | F67: 8448.5275 | I67: 6050.7832 | K67: 243.66651 | N67: 5487.4979 | O67: 5487.4978 | P67: 0 | Q67: 23728.531 | R67: =O67+E67+I67+J67+K67 -> 15280.004 | S67: =F67+P67 -> 8448.5275
A68: 2008 | B68: octubre | D68: 12589.636 | E68: 4281.725 | F68: 8307.9114 | I68: 3088.5711 | J68: 945.4552 | K68: 487.41078 | N68: 9062.4818 | O68: 9062.4818 | P68: 0 | Q68: 26173.555 | R68: =O68+E68+I68+J68+K68 -> 17865.644 | S68: =F68+P68 -> 8307.9114
A69: 2008 | B69: noviembre | D69: 10811.583 | E69: 3611.9968 | F69: 7199.5863 | I69: 1774.1434 | K69: 728.00246 | N69: 9399.8331 | O69: 9399.8329 | P69: 0 | Q69: 22713.562 | R69: =O69+E69+I69+J69+K69 -> 15513.976 | S69: =F69+P69 -> 7199.5863
A70: 2008 | B70: diciembre | D70: 9741.2073 | E70: 3668.6501 | F70: 6072.5572 | I70: 4593.2987 | K70: 727.74471 | N70: 4260.0753 | O70: 4260.0754 | P70: 0 | Q70: 19322.326 | R70: =O70+E70+I70+J70+K70 -> 13249.769 | S70: =F70+P70 -> 6072.5572
A71: 2008 | B71: total | D71: 155287.85 | E71: 51622.882 | F71: 103664.96 | I71: 51835.279 | J71: 945.4552 | K71: 6090.3414 | N71: 92608.487 | O71: =SUM(O59:O70) -> 92608.487 | P71: 0 | Q71: 306767.41 | R71: =O71+E71+I71+J71+K71 -> 203102.44 | S71: =F71+P71 -> 103664.96
A72: 2009 | B72: enero | D72: 10534.202 | E72: 2530.3732 | F72: 8003.8293 | I72: 7299.8898 | K72: 729.22405 | N72: 4851.4981 | O72: 4851.4981 | P72: 0 | Q72: 23414.814 | R72: =O72+E72+I72+J72+K72 -> 15410.985 | S72: =F72+P72 -> 8003.8293
A73: 2009 | B73: febrero | D73: 10154.861 | E73: 4209.3657 | F73: 5945.4951 | I73: 4538.6113 | K73: 729.938 | N73: 3575.6432 | O73: 3575.6432 | P73: 0 | Q73: 18999.053 | R73: =O73+E73+I73+J73+K73 -> 13053.558 | S73: =F73+P73 -> 5945.4951
A74: 2009 | B74: marzo | D74: 9344.1313 | E74: 4172.5603 | F74: 5171.571 | I74: 4347.0653 | K74: 974.7931 | N74: 2773.7528 | O74: 2773.7528 | P74: 0 | Q74: 17439.743 | R74: =O74+E74+I74+J74+K74 -> 12268.172 | S74: =F74+P74 -> 5171.571
A75: 2009 | B75: abril | D75: 10327.625 | E75: 4079.2301 | F75: 6248.3952 | I75: 3838.4573 | K75: 729.70485 | N75: 2554.8032 | O75: 2554.8032 | P75: 0 | Q75: 17450.591 | R75: =O75+E75+I75+J75+K75 -> 11202.195 | S75: =F75+P75 -> 6248.3952
A76: 2009 | B76: mayo | D76: 10805.019 | E76: 4334.9685 | F76: 6470.0503 | I76: 3673.6112 | K76: 728.77166 | N76: 4611.7839 | O76: 4611.7839 | P76: 0 | Q76: 19819.186 | R76: =O76+E76+I76+J76+K76 -> 13349.135 | S76: =F76+P76 -> 6470.0503
A77: 2009 | B77: junio | D77: 12495.706 | E77: 5436.0634 | F77: 7059.6422 | I77: 6349.3403 | K77: 729.987 | N77: 3678.4042 | O77: 3678.4042 | P77: 0 | Q77: 23253.437 | R77: =O77+E77+I77+J77+K77 -> 16193.795 | S77: =F77+P77 -> 7059.6422
A78: 2009 | B78: julio | D78: 13218.704 | E78: 6284.2875 | F78: 6934.4167 | I78: 3712.1409 | K78: 732.75475 | N78: 5562.0715 | O78: 5562.0715 | P78: 0 | Q78: 23225.671 | R78: =O78+E78+I78+J78+K78 -> 16291.255 | S78: =F78+P78 -> 6934.4167
A79: 2009 | B79: agosto | D79: 11777.441 | E79: 5840.776 | F79: 5936.665 | I79: 3711.7989 | K79: 235.89524 | N79: 3679.7094 | O79: 3679.7094 | P79: 0 | Q79: 19404.844 | R79: =O79+E79+I79+J79+K79 -> 13468.18 | S79: =F79+P79 -> 5936.665
A80: 2009 | B80: septiembre | D80: 14604.631 | E80: 7442.607 | F80: 7162.0239 | I80: 2665.6371 | K80: 718.1207 | N80: 4430.6453 | O80: 4430.6453 | P80: 0 | Q80: 22419.034 | R80: =O80+E80+I80+J80+K80 -> 15257.01 | S80: =F80+P80 -> 7162.0239
A81: 2009 | B81: octubre | D81: 10574.505 | E81: 4976.2038 | F81: 5598.301 | I81: 5516.4729 | K81: 726.84145 | N81: 3451.0356 | O81: 3451.0356 | P81: 0 | Q81: 20268.855 | R81: =O81+E81+I81+J81+K81 -> 14670.554 | S81: =F81+P81 -> 5598.301
...

Sheet América
D3: =Inicio!C4 -> Importaciones de gas natural por áreas geográficas y países
A4: =Inicio!$A$16 -> Actualizado el 14-09-2026 | I4: Unidad: gigavatio hora
C5: América
A6: Año | B6: Mes | C6: Argentina GNL | D6: Estados Unidos GNL | E6: Jamaica GNL | F6: México GNL | G6: Perú GNL | H6: Trinidad y Tobago GNL | I6: Total América GNL
A7: 2004 | B7: enero
A8: 2004 | B8: febrero
A9: 2004 | B9: marzo
A10: 2004 | B10: abril
A11: 2004 | B11: mayo
A12: 2004 | B12: junio
A13: 2004 | B13: julio
A14: 2004 | B14: agosto
A15: 2004 | B15: septiembre
A16: 2004 | B16: octubre
A17: 2004 | B17: noviembre
A18: 2004 | B18: diciembre
... A21: 2005 | B21: febrero
A22: 2005 | B22: marzo | H22: 1499.8499 | I22: 1499.8499
A23: 2005 | B23: abril
A24: 2005 | B24: mayo
A25: 2005 | B25: junio
A26: 2005 | B26: julio
A27: 2005 | B27: agosto
A28: 2005 | B28: septiembre
A29: 2005 | B29: octubre | H29: 616.30449 | I29: 616.30449
A30: 2005 | B30: noviembre | H30: 835.51528 | I30: 835.51528
A31: 2005 | B31: diciembre | H31: 1580.3357 | I31: 1580.3357
A32: 2005 | B32: total | H32: 4532.0053 | I32: 4532.0053
A33: 2006 | B33: enero | H33: 3423.3967 | I33: 3423.3967
A34: 2006 | B34: febrero | H34: 4738.7369 | I34: 4738.7369
A35: 2006 | B35: marzo | H35: 4324.7226 | I35: 4324.7226
A36: 2006 | B36: abril | H36: 3050.8692 | I36: 3050.8692
A37: 2006 | B37: mayo | H37: 2204.3317 | I37: 2204.3317
A38: 2006 | B38: junio | H38: 1907.1931 | I38: 1907.1931
A39: 2006 | B39: julio | H39: 3885.9681 | I39: 3885.9681
A40: 2006 | B40: agosto | H40: 2228.1254 | I40: 2228.1254
... A91: 2010 | B91: julio | H91: 3006.5008 | I91: 3006.5008
A92: 2010 | B92: agosto | G92: 3110.6807 | H92: 854.3308 | I92: 3965.0115
A93: 2010 | B93: septiembre | H93: 1550.6321 | I93: 1550.6321
A94: 2010 | B94: octubre | G94: 2076.5309 | H94: 5347.0929 | I94: 7423.6238
...

Sheet Europa y Euroasia
C3: =Inicio!C4 -> Importaciones de gas natural por áreas geográficas y países
A4: =Inicio!$A$16 -> Actualizado el 14-09-2026 | AA4: Unidad: gigavatio hora
C5: Europa
A6: Año | B6: Mes | C6: Bélgica | D6: Bélgica GNL | E6: Bélgica GN | F6: Francia | G6: Francia GNL | H6: Francia GN | I6: Gibraltar GNL | J6: Noruega | K6: Noruega GNL | L6: Noruega GN | M6: Países Bajos | N6: Países Bajos GNL | O6: Países Bajos GN | P6: Portugal | Q6: Portugal GNL | R6: Portugal GN | S6: Reino Unido | T6: Reino Unido GNL | U6: Reino Unido GN | V6: Rusia | W6: Rusia GNL | X6: Rusia GN | Y6: Total Europa y Euroasia | Z6: Europa y Euroasia GNL | AA6: Europa y Euroasia GN
A7: 2004 | B7: enero | J7: 2153.9588 | K7: 0 | L7: 2153.959 | Y7: 2153.9588 | Z7: =E7+G7+N7+K7+Q7 -> 0 | AA7: =H7+O7+L7+R7+X7+U7 -> 2153.959
A8: 2004 | B8: febrero | F8: 37.263 | G8: 37.263 | J8: 2137.8933 | K8: 0 | L8: 2137.8933 | M8: 10.322044 | O8: 10.322044 | S8: 4.4464188 | U8: 4.4464188 | V8: 19.373682 | X8: 19.373682 | Y8: 2209.2985 | Z8: =E8+G8+N8+K8+Q8 -> 37.263 | AA8: =H8+O8+L8+R8+X8+U8 -> 2172.0355
A9: 2004 | B9: marzo | G9: 0 | J9: 2269.9738 | K9: 0 | L9: 2269.9741 | M9: 6.6197342 | O9: 6.6197342 | S9: 2.8515778 | U9: 2.8515778 | V9: 12.424732 | X9: 12.424732 | Y9: 2291.8698 | Z9: =E9+G9+N9+K9+Q9 -> 0 | AA9: =H9+O9+L9+R9+X9+U9 -> 2291.8701
A10: 2004 | B10: abril | G10: 0 | J10: 2188.6465 | K10: 0 | L10: 2188.6468 | M10: 1.64554 | O10: 1.64554 | S10: 0.708848 | U10: 0.708848 | V10: 3.088552 | X10: 3.088552 | Y10: 2194.0895 | Z10: =E10+G10+N10+K10+Q10 -> 0 | AA10: =H10+O10+L10+R10+X10+U10 -> 2194.0898
A11: 2004 | B11: mayo | F11: 38.666 | G11: 38.666 | J11: 2251.8541 | K11: 0 | L11: 2251.8542 | M11: 2.0852192 | O11: 2.0852192 | S11: 0.89824829 | U11: 0.89824829 | V11: 3.9137961 | X11: 3.9137961 | Y11: 2297.4173 | Z11: =E11+G11+N11+K11+Q11 -> 38.666 | AA11: =H11+O11+L11+R11+X11+U11 -> 2258.7514
A12: 2004 | B12: junio | G12: 0 | J12: 2137.3001 | K12: 0 | L12: 2137.3002 | M12: 13.161373 | O12: 13.161373 | S12: 5.6695147 | U12: 5.6695147 | V12: 24.702885 | X12: 24.702885 | Y12: 2180.8338 | Z12: =E12+G12+N12+K12+Q12 -> 0 | AA12: =H12+O12+L12+R12+X12+U12 -> 2180.8339
A13: 2004 | B13: julio | F13: 38.235 | G13: 38.235 | J13: 2131.2794 | K13: 0 | L13: 2131.28 | Y13: 2169.5144 | Z13: =E13+G13+N13+K13+Q13 -> 38.235 | AA13: =H13+O13+L13+R13+X13+U13 -> 2131.28
A14: 2004 | B14: agosto | G14: 0 | J14: 1702.1257 | K14: 0 | L14: 1702.126 | Y14: 1702.1257 | Z14: =E14+G14+N14+K14+Q14 -> 0 | AA14: =H14+O14+L14+R14+X14+U14 -> 1702.126
A15: 2004 | B15: septiembre | G15: 0 | J15: 2135.4753 | K15: 0 | L15: 2135.4754 | M15: 4.8442525 | O15: 4.8442525 | S15: 2.0867549 | U15: 2.0867549 | V15: 9.0922894 | X15: 9.0922894 | Y15: 2151.4986 | Z15: =E15+G15+N15+K15+Q15 -> 0 | AA15: =H15+O15+L15+R15+X15+U15 -> 2151.4987
A16: 2004 | B16: octubre | G16: 0 | J16: 2285.1339 | K16: 0 | L16: 2285.1339 | M16: 13.600823 | O16: 13.600823 | S16: 5.8588159 | U16: 5.8588159 | V16: 25.527698 | X16: 25.527698 | Y16: 2330.1212 | Z16: =E16+G16+N16+K16+Q16 -> 0 | AA16: =H16+O16+L16+R16+X16+U16 -> 2330.1213
A17: 2004 | B17: noviembre | F17: 73.5 | G17: 73.5 | J17: 2210.912 | K17: 0 | L17: 2210.912 | M17: 13.175168 | O17: 13.175168 | S17: 5.6754569 | U17: 5.6754569 | V17: 24.728776 | X17: 24.728776 | Y17: 2327.9914 | Z17: =E17+G17+N17+K17+Q17 -> 73.5 | AA17: =H17+O17+L17+R17+X17+U17 -> 2254.4914
A18: 2004 | B18: diciembre | J18: 2279.6882 | K18: 0 | L18: 2279.688 | M18: 13.585016 | O18: 13.585016 | S18: 5.8520068 | U18: 5.8520068 | V18: 25.49803 | X18: 25.49803 | Y18: 2324.6233 | Z18: =E18+G18+N18+K18+Q18 -> 0 | AA18: =H18+O18+L18+R18+X18+U18 -> 2324.6231
A19: 2004 | B19: total | F19: 187.664 | G19: 187.664 | J19: 25884.241 | K19: =SUM(K7:K18) -> 0 | L19: =SUM(L7:L18) -> 25884.243 | M19: 79.039169 | O19: 79.039169 | S19: 34.047642 | U19: 34.047642 | V19: 148.35044 | X19: 148.35044 | Y19: 26333.342 | Z19: =E19+G19+N19+K19+Q19 -> 187.664 | AA19: =H19+O19+L19+R19+X19+U19 -> 26145.68
A20: 2005 | B20: enero | F20: 63.75 | G20: 63.75 | J20: 2262.1122 | K20: 0 | L20: 2262.112 | Y20: 2325.8622 | Z20: =E20+G20+N20+K20+Q20 -> 63.75 | AA20: =H20+O20+L20+R20+X20 -> 2262.112
A21: 2005 | B21: febrero | J21: 2046.6952 | K21: 0 | L21: 2046.695 | Y21: 2046.6952 | Z21: =E21+G21+N21+K21+Q21 -> 0 | AA21: =H21+O21+L21+R21+X21 -> 2046.695
A22: 2005 | B22: marzo | F22: 56.393 | G22: 56.393 | J22: 2249.548 | K22: 0 | L22: 2249.548 | Y22: 2305.941 | Z22: =E22+G22+N22+K22+Q22 -> 56.393 | AA22: =H22+O22+L22+R22+X22 -> 2249.548
A23: 2005 | B23: abril | F23: 55.273 | G23: 55.273 | J23: 2188.0941 | K23: 0 | L23: 2188.094 | Y23: 2243.3671 | Z23: =E23+G23+N23+K23+Q23 -> 55.273 | AA23: =H23+O23+L23+R23+X23 -> 2188.094
A24: 2005 | B24: mayo | J24: 2058.7623 | K24: 0 | L24: 2058.762 | Y24: 2058.7623 | Z24: =E24+G24+N24+K24+Q24 -> 0 | AA24: =H24+O24+L24+R24+X24 -> 2058.762
A25: 2005 | B25: junio | F25: 43.783774 | G25: 37.943 | H25: 5.84077 | J25: 2153.5524 | K25: 0 | L25: 2153.553 | Y25: 2197.3362 | Z25: =E25+G25+N25+K25+Q25 -> 37.943 | AA25: =H25+O25+L25+R25+X25 -> 2159.3938
A26: 2005 | B26: julio | F26: 359.65589 | G26: 359.6559 | J26: 1683.0372 | K26: 0 | L26: 1683.037 | Y26: 2042.6931 | Z26: =E26+G26+N26+K26+Q26 -> 359.6559 | AA26: =H26+O26+L26+R26+X26 -> 1683.037
A27: 2005 | B27: agosto | F27: 11.946093 | H27: 11.94609 | J27: 1430.5126 | K27: 0 | L27: 1430.513 | Y27: 1442.4587 | Z27: =E27+G27+N27+K27+Q27 -> 0 | AA27: =H27+O27+L27+R27+X27 -> 1442.4591
A28: 2005 | B28: septiembre | F28: 246.03386 | G28: 230.0339 | H28: 16 | J28: 1952.1245 | K28: 0 | L28: 1952.125 | Y28: 2198.1583 | Z28: =E28+G28+N28+K28+Q28 -> 230.0339 | AA28: =H28+O28+L28+R28+X28 -> 1968.125
A29: 2005 | B29: octubre | J29: 2262.6967 | K29: 0 | L29: 2262.697 | Y29: 2262.6967 | Z29: =E29+G29+N29+K29+Q29 -> 0 | AA29: =H29+O29+L29+R29+X29 -> 2262.697
A30: 2005 | B30: noviembre | J30: 2173.724 | K30: 0 | L30: 2173.724 | Y30: 2173.724 | Z30: =E30+G30+N30+K30+Q30 -> 0 | AA30: =H30+O30+L30+R30+X30 -> 2173.724
A31: 2005 | B31: diciembre | J31: 2262.01 | K31: 0 | L31: 2262.01 | Y31: 2262.01 | Z31: =E31+G31+N31+K31+Q31 -> 0 | AA31: =H31+O31+L31+R31+X31 -> 2262.01
A32: 2005 | B32: total | F32: 836.83562 | G32: 803.0488 | H32: 33.78686 | J32: 24722.869 | K32: =SUM(K20:K31) -> 0 | L32: =SUM(L20:L31) -> 24722.87 | Y32: 25559.705 | Z32: =E32+G32+N32+K32+Q32 -> 803.0488 | AA32: =H32+O32+L32+R32+X32 -> 24756.657
A33: 2006 | B33: enero | F33: 124 | H33: 124 | J33: 2255.2171 | K33: 0 | L33: 2255.217 | Y33: 2379.2171 | Z33: =E33+G33+N33+K33+Q33 -> 0 | AA33: =H33+O33+L33+R33+X33 -> 2379.217
A34: 2006 | B34: febrero | F34: 112 | H34: 112 | J34: 2043.8492 | K34: 0 | L34: 2043.849 | Y34: 2155.8492 | Z34: =E34+G34+N34+K34+Q34 -> 0 | AA34: =H34+O34+L34+R34+X34 -> 2155.849
A35: 2006 | B35: marzo | F35: 248.39869 | H35: 248.3987 | J35: 2235.0571 | K35: 0 | L35: 2235.057 | Y35: 2483.4558 | Z35: =E35+G35+N35+K35+Q35 -> 0 | AA35: =H35+O35+L35+R35+X35 -> 2483.4557
A36: 2006 | B36: abril | F36: 126.68739 | H36: 126.6874 | J36: 1021.764 | K36: 0 | L36: 1021.764 | Y36: 1148.4514 | Z36: =E36+G36+N36+K36+Q36 -> 0 | AA36: =H36+O36+L36+R36+X36 -> 1148.4514
A37: 2006 | B37: mayo | F37: 123.45705 | H37: 123.4571 | J37: 2215.2003 | K37: 0 | L37: 2215.2 | Y37: 2338.6574 | Z37: =E37+G37+N37+K37+Q37 -> 0 | AA37: =H37+O37+L37+R37+X37 -> 2338.6571
A38: 2006 | B38: junio | F38: 119.339 | H38: 119.339 | J38: 1978.5108 | K38: 0 | L38: 1978.511 | Y38: 2097.8498 | Z38: =E38+G38+N38+K38+Q38 -> 0 | AA38: =H38+O38+L38+R38+X38 -> 2097.85
A39: 2006 | B39: julio | J39: 2042.6012 | K39: 0 | L39: 2042.601 | Y39: 2042.6012 | Z39: =E39+G39+N39+K39+Q39 -> 0 | AA39: =H39+O39+L39+R39+X39 -> 2042.601
A40: 2006 | B40: agosto | J40: 2003.8353 | K40: 0 | L40: 2003.835 | Y40: 2003.8353 | Z40: =E40+G40+N40+K40+Q40 -> 0 | AA40: =H40+O40+L40+R40+X40 -> 2003.835
A41: 2006 | B41: septiembre | J41: 2188.9251 | K41: 0 | L41: 2188.925 | Y41: 2188.9251 | Z41: =E41+G41+N41+K41+Q41 -> 0 | AA41: =H41+O41+L41+R41+X41 -> 2188.925
A42: 2006 | B42: octubre | J42: 2043.2737 | K42: 0 | L42: 2043.274 | Y42: 2043.2737 | Z42: =E42+G42+N42+K42+Q42 -> 0 | AA42: =H42+O42+L42+R42+X42 -> 2043.274
...

Sheet Oriente Medio
C3: =Inicio!C4 -> Importaciones de gas natural por áreas geográficas y países
A4: =Inicio!$A$16 -> Actualizado el 14-09-2026 | G4: Unidad: gigavatio hora
C5: Oriente Medio
A6: Año | B6: Mes | C6: EAU GNL | D6: Omán GNL | E6: Qatar GNL | F6: Yemen GNL | G6: Total OM GNL
A7: 2004 | B7: enero | E7: 3079.5713 | G7: 3079.5713
A8: 2004 | B8: febrero | D8: 922.02128 | E8: 2474.5893 | G8: 3396.6106
A9: 2004 | B9: marzo | C9: 930.76397 | E9: 1772.867 | G9: 2703.631
A10: 2004 | B10: abril | D10: 937.25585 | E10: 3229.7107 | G10: 4166.9666
A11: 2004 | B11: mayo | C11: 919.43697 | D11: 1442.4969 | E11: 5032.2867 | G11: 7394.2205
A12: 2004 | B12: junio | D12: 2704.819 | E12: 4276.6913 | G12: 6981.5103
A13: 2004 | B13: julio | D13: 909.43 | E13: 6227.5386 | G13: 7136.9686
A14: 2004 | B14: agosto | C14: 914.3799 | D14: 971.76728 | E14: 4378.9525 | G14: 6265.0997
A15: 2004 | B15: septiembre | D15: 1836.0294 | E15: 4385.8424 | G15: 6221.8718
A16: 2004 | B16: octubre | E16: 3201.5102 | G16: 3201.5102
A17: 2004 | B17: noviembre | D17: 2718.3029 | E17: 4074.5101 | G17: 6792.8129
A18: 2004 | B18: diciembre | C18: 907.84452 | D18: 1845.7956 | E18: 2549.5411 | G18: 5303.1812
A19: 2004 | B19: total | C19: 3672.4254 | D19: 14287.918 | E19: 44683.611 | G19: 62643.955
A20: 2005 | B20: enero | C20: 929.00525 | D20: 1823.5206 | E20: 4301.9349 | G20: 7054.4608
A21: 2005 | B21: febrero | C21: 908.65111 | D21: 1748.2218 | E21: 3711.8448 | G21: 6368.7177
A22: 2005 | B22: marzo | C22: 920.90715 | D22: 1627.5263 | E22: 3436.9731 | G22: 5985.4066
A23: 2005 | B23: abril | D23: 1776.8265 | E23: 5294.22 | G23: 7071.0464
A24: 2005 | B24: mayo | D24: 376.78073 | E24: 5468.7582 | G24: 5845.5389
A25: 2005 | B25: junio | D25: 1917.0832 | E25: 5036.7295 | G25: 6953.8126
A26: 2005 | B26: julio | D26: 2399.8331 | E26: 4892.8305 | G26: 7292.6636
A27: 2005 | B27: agosto | D27: 924.67049 | E27: 5760.963 | G27: 6685.6335
A28: 2005 | B28: septiembre | D28: 1851.3726 | E28: 6212.8716 | G28: 8064.2442
A29: 2005 | B29: octubre | D29: 2499.5093 | E29: 3941.1337 | G29: 6440.643
A30: 2005 | B30: noviembre | D30: 290 | E30: 3733.4382 | G30: 4023.4382
A31: 2005 | B31: diciembre | D31: 2588.7175 | E31: 2563.2697 | G31: 5151.9871
A32: 2005 | B32: total | C32: 2758.5635 | D32: 19824.062 | E32: 54354.967 | G32: 76937.593
A33: 2006 | B33: enero | D33: 993.90399 | E33: 4338.5477 | G33: 5332.4517
A34: 2006 | B34: febrero | D34: 1893.2641 | E34: 3087.1557 | G34: 4980.4198
A35: 2006 | B35: marzo | D35: 990.11776 | E35: 3443.8572 | G35: 4433.9749
A36: 2006 | B36: abril | D36: 801.37448 | E36: 5534.1148 | G36: 6335.4893
A37: 2006 | B37: mayo | E37: 5872.105 | G37: 5872.105
A38: 2006 | B38: junio | E38: 6269.1371 | G38: 6269.1371
A39: 2006 | B39: julio | D39: 1904.64 | E39: 8427.607 | G39: 10332.247
A40: 2006 | B40: agosto | E40: 6404.3792 | G40: 6404.3792
A41: 2006 | B41: septiembre | E41: 4467.2736 | G41: 4467.2736
A42: 2006 | B42: octubre | D42: 1470.6379 | E42: 4947.1735 | G42: 6417.8115
...

Sheet Asia-Pacífico
C3: =Inicio!C4 -> Importaciones de gas natural por áreas geográficas y países
A4: =Inicio!$A$16 -> Actualizado el 14-09-2026 | I4: Unidad: gigavatio hora
C5: Asia-Pacífico
A6: Año | B6: Mes | C6: Australia GNL | D6: Brunei GNL | E6: Corea del Sur GNL | F6: Indonesia GNL | G6: Malasia GNL | H6: Papúa Nueva Guinea GNL | I6: Total Asia-Pacífico GNL
A7: 2004 | B7: enero
A8: 2004 | B8: febrero
A9: 2004 | B9: marzo
A10: 2004 | B10: abril
A11: 2004 | B11: mayo
A12: 2004 | B12: junio
A13: 2004 | B13: julio
A14: 2004 | B14: agosto
A15: 2004 | B15: septiembre
A16: 2004 | B16: octubre
A17: 2004 | B17: noviembre
A18: 2004 | B18: diciembre | G18: 912.10881 | I18: 912.10881
A19: 2004 | B19: total | G19: 912.10881 | I19: 912.10881
A20: 2005 | B20: enero | G20: 2128.9972 | I20: 2128.9972
A21: 2005 | B21: febrero | G21: 911.83949 | I21: 911.83949
A22: 2005 | B22: marzo
A23: 2005 | B23: abril
A24: 2005 | B24: mayo
A25: 2005 | B25: junio
A26: 2005 | B26: julio
A27: 2005 | B27: agosto
A28: 2005 | B28: septiembre
A29: 2005 | B29: octubre
A30: 2005 | B30: noviembre
A31: 2005 | B31: diciembre
A32: 2005 | B32: total | G32: 3040.8367 | I32: 3040.8367
A33: 2006 | B33: enero
A34: 2006 | B34: febrero
A35: 2006 | B35: marzo
A36: 2006 | B36: abril
A37: 2006 | B37: mayo
A38: 2006 | B38: junio
A39: 2006 | B39: julio
A40: 2006 | B40: agosto
A41: 2006 | B41: septiembre
A42: 2006 | B42: octubre
...

Sheet Todos
C3: =África!C3 -> Importaciones de gas natural por áreas geográficas y países
A4: =Inicio!$A$16 -> Actualizado el 14-09-2026 | BS4: Unidad: gigavatio hora
C5: África | U5: América | AC5: Europa y Euroasia | BC5: Oriente Medio | BI5: Asia-Pacífico | BQ5: Total | BR5: Total GNL | BS5: Total GN
A6: Año | B6: Mes | C6: Angola GNL | D6: Argelia | E6: Argelia GNL | F6: Argelia GN | G6: Camerún GNL | H6: Congo GNL | I6: Egipto GNL | J6: Guinea Ecuatorial GNL | K6: Libia GNL | L6: Mauritania GNL | M6: Mozambique GNL | N6: Nigeria | O6: Nigeria GNL | P6: Nigeria GN | Q6: Total África | R6: Total África GNL | S6: Total África GN | U6: Argentina GNL | V6: Estados Unidos GNL | W6: Jamaica GNL | X6: México GNL | Y6: Perú GNL | Z6: Trinidad y Tobago GNL | AA6: Total América GNL | AC6: Bélgica | AD6: Bélgica GNL | AE6: Bélgica GN | AF6: Francia | AG6: Francia GNL | AH6: Francia GN | AI6: Gibraltar GNL | AJ6: Noruega | AK6: Noruega GNL | AL6: Noruega GN | AM6: Países Bajos | AN6: Países Bajos GNL | AO6: Países Bajos GN | AP6: Portugal | AQ6: Portugal GNL | AR6: Portugal GN | AS6: Reino Unido | AT6: Reino Unido GNL | AU6: Reino Unido GN | AV6: Rusia | AW6: Rusia GNL | AX6: Rusia GN | AY6: Total Europa y Euroasia | AZ6: Europa y Euroasia GNL | BA6: Europa y Euroasia GN | BC6: EAU GNL | BD6: Omán GNL | BE6: Qatar GNL | BF6: Yemen GNL | BG6: Total OM GNL | BI6: Australia GNL | BJ6: Brunei GNL | BK6: Corea del Sur GNL | BL6: Indonesia GNL | BM6: Malasia GNL | BN6: Papúa Nueva Guinea GNL | BO6: Total Asia-Pacífico GNL
A7: 2004 | B7: enero | D7: 15667.722 | E7: 9155.8528 | F7: 6511.869 | I7: 0 | J7: 0 | K7: 723.8085 | N7: 4533.35 | O7: 4533.35 | P7: 0 | Q7: 20924.88 | R7: 14413.011 | S7: 6511.869 | Y7: 0 | Z7: 0 | AA7: 0 | AC7: 0 | AD7: 0 | AF7: 0 | AG7: 0 | AH7: 0 | AJ7: 2153.9588 | AK7: 0 | AL7: 2153.959 | AM7: 0 | AN7: 0 | AO7: 0 | AP7: 0 | AQ7: 0 | AR7: 0 | AU7: 0 | AX7: 0 | AY7: 2153.9588 | AZ7: 0 | BA7: 2153.959 | BC7: 0 | BD7: 0 | BE7: 3079.5713 | BF7: 0 | BG7: 3079.5713 | BI7: 0 | BJ7: 0 | BM7: 0 | BO7: 0 | BQ7: 26158.41 | BR7: 17492.583 | BS7: 8665.828
A8: 2004 | B8: febrero | D8: 14909.618 | E8: 7712.4968 | F8: 7197.1213 | I8: 0 | J8: 0 | K8: 723.7128 | N8: 3856.8568 | O8: 3518.4752 | P8: 338.38161 | Q8: 19490.188 | R8: 11954.685 | S8: 7535.5029 | Y8: 0 | Z8: 0 | AA8: 0 | AC8: 0 | AD8: 0 | AF8: 37.263 | AG8: 37.263 | AH8: 0 | AJ8: 2137.8933 | AK8: 0 | AL8: 2137.8933 | AM8: 10.322044 | AN8: 0 | AO8: 10.322044 | AP8: 0 | AQ8: 0 | AR8: 0 | AS8: 4.4464188 | AU8: 4.4464188 | AV8: 19.373682 | AX8: 19.373682 | AY8: 2209.2985 | AZ8: 37.263 | BA8: 2172.0355 | BC8: 0 | BD8: 922.02128 | BE8: 2474.5893 | BF8: 0 | BG8: 3396.6106 | BI8: 0 | BJ8: 0 | BM8: 0 | BO8: 0 | BQ8: 25096.097 | BR8: 15388.558 | BS8: 9707.5383
A9: 2004 | B9: marzo | D9: 14662.131 | E9: 6418.8038 | F9: 8243.327 | I9: 0 | J9: 0 | K9: 732.0007 | N9: 5546.4526 | O9: 5208.0997 | P9: 338.35289 | Q9: 20940.584 | R9: 12358.904 | S9: 8581.6799 | Y9: 0 | Z9: 0 | AA9: 0 | AC9: 0 | AD9: 0 | AF9: 0 | AG9: 0 | AH9: 0 | AJ9: 2269.9738 | AK9: 0 | AL9: 2269.9741 | AM9: 6.6197342 | AN9: 0 | AO9: 6.6197342 | AP9: 0 | AQ9: 0 | AR9: 0 | AS9: 2.8515778 | AU9: 2.8515778 | AV9: 12.424732 | AX9: 12.424732 | AY9: 2291.8698 | AZ9: 0 | BA9: 2291.8701 | BC9: 930.76397 | BD9: 0 | BE9: 1772.867 | BF9: 0 | BG9: 2703.631 | BI9: 0 | BJ9: 0 | BM9: 0 | BO9: 0 | BQ9: 25936.085 | BR9: 15062.535 | BS9: 10873.55
A10: 2004 | B10: abril | D10: 11929.376 | E10: 6651.0921 | F10: 5278.284 | I10: 0 | J10: 0 | K10: 487.0423 | N10: 4448.7712 | O10: 4448.594 | P10: 0.17721 | Q10: 16865.19 | R10: 11586.728 | S10: 5278.4612 | Y10: 0 | Z10: 0 | AA10: 0 | AC10: 0 | AD10: 0 | AF10: 0 | AG10: 0 | AH10: 0 | AJ10: 2188.6465 | AK10: 0 | AL10: 2188.6468 | AM10: 1.64554 | AN10: 0 | AO10: 1.64554 | AP10: 0 | AQ10: 0 | AR10: 0 | AS10: 0.708848 | AU10: 0.708848 | AV10: 3.088552 | AX10: 3.088552 | AY10: 2194.0895 | AZ10: 0 | BA10: 2194.0898 | BC10: 0 | BD10: 937.25585 | BE10: 3229.7107 | BF10: 0 | BG10: 4166.9666 | BI10: 0 | BJ10: 0 | BM10: 0 | BO10: 0 | BQ10: 23226.246 | BR10: 15753.695 | BS10: 7472.551
A11: 2004 | B11: mayo | D11: 10727.015 | E11: 5406.4592 | F11: 5320.5562 | I11: 0 | J11: 0 | K11: 971.6548 | N11: 5848.4457 | O11: 5615.6211 | P11: 232.82456 | Q11: 17547.116 | R11: 11993.735 | S11: 5553.3807 | Y11: 0 | Z11: 0 | AA11: 0 | AC11: 0 | AD11: 0 | AF11: 38.666 | AG11: 38.666 | AH11: 0 | AJ11: 2251.8541 | AK11: 0 | AL11: 2251.8542 | AM11: 2.0852192 | AN11: 0 | AO11: 2.0852192 | AP11: 0 | AQ11: 0 | AR11: 0 | AS11: 0.89824829 | AU11: 0.89824829 | AV11: 3.9137961 | AX11: 3.9137961 | AY11: 2297.4173 | AZ11: 38.666 | BA11: 2258.7514 | BC11: 919.43697 | BD11: 1442.4969 | BE11: 5032.2867 | BF11: 0 | BG11: 7394.2205 | BI11: 0 | BJ11: 0 | BM11: 0 | BO11: 0 | BQ11: 27238.754 | BR11: 19426.622 | BS11: 7812.1321
A12: 2004 | B12: junio | D12: 10148.506 | E12: 3944.8118 | F12: 6203.6943 | I12: 0 | J12: 0 | K12: 728.8337 | N12: 4875.7018 | O12: 4874.2844 | P12: 1.41738 | Q12: 15753.042 | R12: 9547.9299 | S12: 6205.1117 | Y12: 0 | Z12: 0 | AA12: 0 | AC12: 0 | AD12: 0 | AF12: 0 | AG12: 0 | AH12: 0 | AJ12: 2137.3001 | AK12: 0 | AL12: 2137.3002 | AM12: 13.161373 | AN12: 0 | AO12: 13.161373 | AP12: 0 | AQ12: 0 | AR12: 0 | AS12: 5.6695147 | AU12: 5.6695147 | AV12: 24.702885 | AX12: 24.702885 | AY12: 2180.8338 | AZ12: 0 | BA12: 2180.8339 | BC12: 0 | BD12: 2704.819 | BE12: 4276.6913 | BF12: 0 | BG12: 6981.5103 | BI12: 0 | BJ12: 0 | BM12: 0 | BO12: 0 | BQ12: 24915.386 | BR12: 16529.44 | BS12: 8385.9456
A13: 2004 | B13: julio | D13: 11933.316 | E13: 5221.3938 | F13: 6711.922 | I13: 0 | J13: 0 | K13: 721.9886 | N13: 4248.3623 | O13: 4248.3623 | P13: 0 | Q13: 16903.667 | R13: 10191.745 | S13: 6711.922 | Y13: 0 | Z13: 0 | AA13: 0 | AC13: 0 | AD13: 0 | AF13: 38.235 | AG13: 38.235 | AH13: 0 | AJ13: 2131.2794 | AK13: 0 | AL13: 2131.28 | AM13: 0 | AN13: 0 | AO13: 0 | AP13: 0 | AQ13: 0 | AR13: 0 | AU13: 0 | AV13: 0 | AX13: 0 | AY13: 2169.5144 | AZ13: 38.235 | BA13: 2131.28 | BC13: 0 | BD13: 909.43 | BE13: 6227.5386 | BF13: 0 | BG13: 7136.9686 | BI13: 0 | BJ13: 0 | BM13: 0 | BO13: 0 | BQ13: 26210.15 | BR13: 17366.948 | BS13: 8843.202
A14: 2004 | B14: agosto | D14: 11155.417 | E14: 5276.8823 | F14: 5878.535 | I14: 0 | J14: 0 | K14: 7.57282 | N14: 4229.1824 | O14: 4229.1824 | P14: 0 | Q14: 15392.172 | R14: 9513.6375 | S14: 5878.535 | Y14: 0 | Z14: 0 | AA14: 0 | AC14: 0 | AD14: 0 | AF14: 0 | AG14: 0 | AH14: 0 | AJ14: 1702.1257 | AK14: 0 | AL14: 1702.126 | AM14: 0 | AN14: 0 | AO14: 0 | AP14: 0 | AQ14: 0 | AR14: 0 | AU14: 0 | AV14: 0 | AX14: 0 | AY14: 1702.1257 | AZ14: 0 | BA14: 1702.126 | BC14: 914.3799 | BD14: 971.76728 | BE14: 4378.9525 | BF14: 0 | BG14: 6265.0997 | BI14: 0 | BJ14: 0 | BM14: 0 | BO14: 0 | BQ14: 23359.398 | BR14: 15778.737 | BS14: 7580.661
A15: 2004 | B15: septiembre | D15: 13280.247 | E15: 5971.9545 | F15: 7308.2921 | I15: 0 | J15: 0 | K15: 477.9151 | N15: 5940.881 | O15: 5940.3593 | P15: 0.52169 | Q15: 19699.043 | R15: 12390.229 | S15: 7308.8138 | Y15: 0 | Z15: 0 | AA15: 0 | AC15: 0 | AD15: 0 | AF15: 0 | AG15: 0 | AH15: 0 | AJ15: 2135.4753 | AK15: 0 | AL15: 2135.4754 | AM15: 4.8442525 | AN15: 0 | AO15: 4.8442525 | AP15: 0 | AQ15: 0 | AR15: 0 | AS15: 2.0867549 | AU15: 2.0867549 | AV15: 9.0922894 | AX15: 9.0922894 | AY15: 2151.4986 | AZ15: 0 | BA15: 2151.4987 | BC15: 0 | BD15: 1836.0294 | BE15: 4385.8424 | BF15: 0 | BG15: 6221.8718 | BI15: 0 | BJ15: 0 | BM15: 0 | BO15: 0 | BQ15: 28072.413 | BR15: 18612.101 | BS15: 9460.3125
A16: 2004 | B16: octubre | D16: 14540.002 | E16: 6340.9898 | F16: 8199.0117 | I16: 0 | J16: 0 | K16: 731.0999 | N16: 5924.2679 | O16: 5922.8032 | P16: 1.4647 | Q16: 21195.369 | R16: 12994.893 | S16: 8200.4765 | Y16: 0 | Z16: 0 | AA16: 0 | AC16: 0 | AD16: 0 | AF16: 0 | AG16: 0 | AH16: 0 | AJ16: 2285.1339 | AK16: 0 | AL16: 2285.1339 | AM16: 13.600823 | AN16: 0 | AO16: 13.600823 | AP16: 0 | AQ16: 0 | AR16: 0 | AS16: 5.8588159 | AU16: 5.8588159 | AV16: 25.527698 | AX16: 25.527698 | AY16: 2330.1212 | AZ16: 0 | BA16: 2330.1213 | BC16: 0 | BD16: 0 | BE16: 3201.5102 | BF16: 0 | BG16: 3201.5102 | BI16: 0 | BJ16: 0 | BM16: 0 | BO16: 0 | BQ16: 26727.001 | BR16: 16196.403 | BS16: 10530.598
A17: 2004 | B17: noviembre | D17: 16333.855 | E17: 7176.234 | F17: 9157.6212 | I17: 0 | J17: 0 | K17: 729.5162 | N17: 4778.395 | O17: 4776.9761 | P17: 1.41886 | Q17: 21841.766 | R17: 12682.726 | S17: 9159.0401 | Y17: 0 | Z17: 0 | AA17: 0 | AC17: 0 | AD17: 0 | AF17: 73.5 | AG17: 73.5 | AH17: 0 | AJ17: 2210.9105 | AK17: 0 | AL17: 2210.9105 | AM17: 13.175164 | AN17: 0 | AO17: 13.175164 | AP17: 0 | AQ17: 0 | AR17: 0 | AS17: 5.6754569 | AU17: 5.6754538 | AV17: 24.728777 | AX17: 24.728777 | AY17: 2327.9905 | AZ17: 73.5 | BA17: 2254.4905 | BC17: 0 | BD17: 2718.303 | BE17: 4074.5101 | BF17: 0 | BG17: 6792.8131 | BI17: 0 | BJ17: 0 | BM17: 0 | BO17: 0 | BQ17: 30962.565 | BR17: 19549.034 | BS17: 11413.532
A18: 2004 | B18: diciembre | D18: 14064.26 | E18: 5795.8041 | F18: 8268.456 | I18: 0 | J18: 0 | K18: 729.7091 | N18: 3458.211 | O18: 3456.748 | P18: 1.463 | Q18: 18252.18 | R18: 9982.2612 | S18: 8269.919 | Y18: 0 | Z18: 0 | AA18: 0 | AC18: 0 | AD18: 0 | AF18: 0 | AG18: 0 | AH18: 0 | AJ18: 2279.6882 | AK18: 0 | AL18: 2279.688 | AM18: 13.585016 | AN18: 0 | AO18: 13.585016 | AP18: 0 | AQ18: 0 | AR18: 0 | AS18: 5.8520068 | AU18: 5.8520068 | AV18: 25.49803 | AX18: 25.49803 | AY18: 2324.6233 | AZ18: 0 | BA18: 2324.6231 | BC18: 907.84452 | BD18: 1845.7956 | BE18: 2549.5411 | BF18: 0 | BG18: 5303.1812 | BI18: 0 | BJ18: 0 | BM18: 912.10881 | BO18: 912.10881 | BQ18: 26792.093 | BR18: 16197.551 | BS18: 10594.542
A19: 2004 | B19: total | D19: 159351.46 | E19: 75072.775 | F19: 84278.69 | I19: 0 | J19: 0 | K19: 7764.8545 | N19: 57688.878 | O19: 56772.856 | P19: 916.0219 | Q19: 224805.2 | R19: 139610.49 | S19: 85194.712 | Y19: 0 | Z19: 0 | AA19: 0 | AC19: 0 | AD19: 0 | AF19: 187.664 | AG19: 187.664 | AH19: 0 | AJ19: 25884.241 | AK19: 0 | AL19: 25884.243 | AM19: 79.039169 | AN19: 0 | AO19: 79.039169 | AP19: 0 | AQ19: 0 | AR19: 0 | AS19: 34.047642 | AU19: 34.047642 | AV19: 148.35044 | AX19: 148.35044 | AY19: 26333.342 | AZ19: 187.664 | BA19: 26145.68 | BC19: 3672.4254 | BD19: 14287.918 | BE19: 44683.611 | BF19: 0 | BG19: 62643.955 | BI19: 0 | BJ19: 0 | BM19: 912.10881 | BO19: 912.10881 | BQ19: 314694.6 | BR19: 203354.21 | BS19: 111340.39
A20: 2005 | B20: enero | D20: 14665.943 | E20: 6462.9608 | F20: 8202.982 | I20: 935.80129 | J20: 0 | K20: 973.3127 | N20: 5399.8771 | O20: 5399.8771 | P20: 0 | Q20: 21974.934 | R20: 13771.952 | S20: 8202.982 | Y20: 0 | Z20: 0 | AA20: 0 | AC20: 0 | AD20: 0 | AF20: 63.75 | AG20: 63.75 | AH20: 0 | AJ20: 2262.1122 | AK20: 0 | AL20: 2262.112 | AM20: 0 | AN20: 0 | AO20: 0 | AP20: 0 | AQ20: 0 | AR20: 0 | AU20: 0 | AX20: 0 | AY20: 2325.8622 | AZ20: 63.75 | BA20: 2262.112 | BC20: 929.00525 | BD20: 1823.5206 | BE20: 4301.9349 | BF20: 0 | BG20: 7054.4608 | BI20: 0 | BJ20: 0 | BM20: 2128.9972 | BO20: 2128.9972 | BQ20: 33484.254 | BR20: 23019.16 | BS20: 10465.094
A21: 2005 | B21: febrero | D21: 15550.862 | E21: 6677.6403 | F21: 8873.2221 | I21: 1774.3622 | J21: 0 | K21: 484.1988 | N21: 4468.432 | O21: 4468.432 | P21: 0 | Q21: 22277.855 | R21: 13404.633 | S21: 8873.2221 | Y21: 0 | Z21: 0 | AA21: 0 | AC21: 0 | AD21: 0 | AF21: 0 | AG21: 0 | AH21: 0 | AJ21: 2046.6952 | AK21: 0 | AL21: 2046.695 | AM21: 0 | AN21: 0 | AO21: 0 | AP21: 0 | AQ21: 0 | AR21: 0 | AU21: 0 | AX21: 0 | AY21: 2046.6952 | AZ21: 0 | BA21: 2046.695 | BC21: 908.65111 | BD21: 1748.2218 | BE21: 3711.8448 | BF21: 0 | BG21: 6368.7177 | BI21: 0 | BJ21: 0 | BM21: 911.83949 | BO21: 911.83949 | BQ21: 31605.108 | BR21: 20685.19 | BS21: 10919.917
A22: 2005 | B22: marzo | D22: 16119.762 | E22: 6676.8743 | F22: 9442.8879 | I22: 1847.038 | J22: 0 | K22: 728.3504 | N22: 6309.7881 | O22: 6309.7881 | P22: 0 | Q22: 25004.939 | R22: 15562.051 | S22: 9442.8879 | Y22: 0 | Z22: 1499.8499 | AA22: 1499.8499 | AC22: 0 | AD22: 0 | AF22: 56.393 | AG22: 56.393 | AH22: 0 | AJ22: 2249.548 | AK22: 0 | AL22: 2249.548 | AM22: 0 | AN22: 0 | AO22: 0 | AP22: 0 | AQ22: 0 | AR22: 0 | AU22: 0 | AX22: 0 | AY22: 2305.941 | AZ22: 56.393 | BA22: 2249.548 | BC22: 920.90715 | BD22: 1627.5263 | BE22: 3436.9731 | BF22: 0 | BG22: 5985.4066 | BI22: 0 | BJ22: 0 | BM22: 0 | BO22: 0 | BQ22: 34796.136 | BR22: 23103.7 | BS22: 11692.436
A23: 2005 | B23: abril | D23: 13439.937 | E23: 4692.3761 | F23: 8747.5606 | I23: 3902.7077 | J23: 0 | K23: 729.3692 | N23: 4672.7844 | O23: 4672.7844 | P23: 0 | Q23: 22744.798 | R23: 13997.237 | S23: 8747.5606 | Y23: 0 | Z23: 0 | AA23: 0 | AC23: 0 | AD23: 0 | AF23: 55.273 | AG23: 55.273 | AH23: 0 | AJ23: 2188.0941 | AK23: 0 | AL23: 2188.094 | AM23: 0 | AN23: 0 | AO23: 0 | AP23: 0 | AQ23: 0 | AR23: 0 | AU23: 0 | AX23: 0 | AY23: 2243.3671 | AZ23: 55.273 | BA23: 2188.094 | BC23: 0 | BD23: 1776.8265 | BE23: 5294.22 | BF23: 0 | BG23: 7071.0464 | BI23: 0 | BJ23: 0 | BM23: 0 | BO23: 0 | BQ23: 32059.212 | BR23: 21123.557 | BS23: 10935.655
A24: 2005 | B24: mayo | D24: 13017.129 | E24: 4048.3016 | F24: 8968.8274 | I24: 1768.0127 | J24: 0 | K24: 731.178 | N24: 5949.7919 | O24: 5949.7919 | P24: 0 | Q24: 21466.112 | R24: 12497.284 | S24: 8968.8274 | Y24: 0 | Z24: 0 | AA24: 0 | AC24: 0 | AD24: 0 | AF24: 0 | AG24: 0 | AH24: 0 | AJ24: 2058.7623 | AK24: 0 | AL24: 2058.762 | AM24: 0 | AN24: 0 | AO24: 0 | AP24: 0 | AQ24: 0 | AR24: 0 | AU24: 0 | AX24: 0 | AY24: 2058.7623 | AZ24: 0 | BA24: 2058.762 | BC24: 0 | BD24: 376.78073 | BE24: 5468.7582 | BF24: 0 | BG24: 5845.5389 | BI24: 0 | BJ24: 0 | BM24: 0 | BO24: 0 | BQ24: 29370.413 | BR24: 18342.823 | BS24: 11027.589
A25: 2005 | B25: junio | D25: 11453.078 | E25: 3149.7107 | F25: 8303.3676 | I25: 4356.2933 | J25: 0 | K25: 728.1881 | N25: 6011.9969 | O25: 6011.9969 | P25: 0 | Q25: 22549.557 | R25: 14246.189 | S25: 8303.3676 | Y25: 0 | Z25: 0 | AA25: 0 | AC25: 0 | AD25: 0 | AF25: 43.783774 | AG25: 37.943 | AH25: 5.84077 | AJ25: 2153.5524 | AK25: 0 | AL25: 2153.553 | AM25: 0 | AN25: 0 | AO25: 0 | AP25: 0 | AQ25: 0 | AR25: 0 | AU25: 0 | AX25: 0 | AY25: 2197.3362 | AZ25: 37.943 | BA25: 2159.3938 | BC25: 0 | BD25: 1917.0832 | BE25: 5036.7295 | BF25: 0 | BG25: 6953.8126 | BI25: 0 | BJ25: 0 | BM25: 0 | BO25: 0 | BQ25: 31700.705 | BR25: 21237.945 | BS25: 10462.761
A26: 2005 | B26: julio | D26: 16171.384 | E26: 7407.3674 | F26: 8764.0165 | I26: 3260.7507 | J26: 0 | K26: 729.3216 | N26: 5236.1041 | O26: 5236.1041 | P26: 0 | Q26: 25397.56 | R26: 16633.544 | S26: 8764.0165 | Y26: 0 | Z26: 0 | AA26: 0 | AC26: 0 | AD26: 0 | AF26: 359.65589 | AG26: 359.6559 | AH26: 0 | AJ26: 1683.0372 | AK26: 0 | AL26: 1683.037 | AM26: 0 | AN26: 0 | AO26: 0 | AP26: 0 | AQ26: 0 | AR26: 0 | AU26: 0 | AX26: 0 | AY26: 2042.6931 | AZ26: 359.6559 | BA26: 1683.037 | BC26: 0 | BD26: 2399.8331 | BE26: 4892.8305 | BF26: 0 | BG26: 7292.6636 | BI26: 0 | BJ26: 0 | BM26: 0 | BO26: 0 | BQ26: 34732.917 | BR26: 24285.863 | BS26: 10447.053
A27: 2005 | B27: agosto | D27: 11982.569 | E27: 4626.8672 | F27: 7355.7015 | I27: 1726.9074 | J27: 0 | K27: 730.015 | N27: 5365.5609 | O27: 5365.5609 | P27: 0 | Q27: 19805.052 | R27: 12449.35 | S27: 7355.7015 | Y27: 0 | Z27: 0 | AA27: 0 | AC27: 0 | AD27: 0 | AF27: 11.946093 | AG27: 0 | AH27: 11.94609 | AJ27: 1430.5126 | AK27: 0 | AL27: 1430.513 | AM27: 0 | AN27: 0 | AO27: 0 | AP27: 0 | AQ27: 0 | AR27: 0 | AU27: 0 | AX27: 0 | AY27: 1442.4587 | AZ27: 0 | BA27: 1442.4591 | BC27: 0 | BD27: 924.67049 | BE27: 5760.963 | BF27: 0 | BG27: 6685.6335 | BI27: 0 | BJ27: 0 | BM27: 0 | BO27: 0 | BQ27: 27933.144 | BR27: 19134.984 | BS27: 8798.1606
A28: 2005 | B28: septiembre | D28: 12390.258 | E28: 4333.0761 | F28: 8057.1817 | I28: 3548.1437 | J28: 0 | K28: 1733.8467 | N28: 1969.9874 | O28: 1969.9874 | P28: 0 | Q28: 19642.236 | R28: 11585.054 | S28: 8057.1817 | Y28: 0 | Z28: 0 | AA28: 0 | AC28: 0 | AD28: 0 | AF28: 246.03386 | AG28: 230.0339 | AH28: 16 | AJ28: 1952.1245 | AK28: 0 | AL28: 1952.125 | AM28: 0 | AN28: 0 | AO28: 0 | AP28: 0 | AQ28: 0 | AR28: 0 | AU28: 0 | AX28: 0 | AY28: 2198.1583 | AZ28: 230.0339 | BA28: 1968.125 | BC28: 0 | BD28: 1851.3726 | BE28: 6212.8716 | BF28: 0 | BG28: 8064.2442 | BI28: 0 | BJ28: 0 | BM28: 0 | BO28: 0 | BQ28: 29904.638 | BR28: 19879.332 | BS28: 10025.307
A29: 2005 | B29: octubre | D29: 12275.163 | E29: 4908.3731 | F29: 7366.7901 | I29: 2491.8417 | J29: 0 | K29: 765.9817 | N29: 4635.6438 | O29: 4635.6438 | P29: 0 | Q29: 20168.63 | R29: 12801.84 | S29: 7366.7901 | Y29: 0 | Z29: 616.30449 | AA29: 616.30449 | AC29: 0 | AD29: 0 | AF29: 0 | AG29: 0 | AH29: 0 | AJ29: 2262.6967 | AK29: 0 | AL29: 2262.697 | AM29: 0 | AN29: 0 | AO29: 0 | AP29: 0 | AQ29: 0 | AR29: 0 | AU29: 0 | AX29: 0 | AY29: 2262.6967 | AZ29: 0 | BA29: 2262.697 | BC29: 0 | BD29: 2499.5093 | BE29: 3941.1337 | BF29: 0 | BG29: 6440.643 | BI29: 0 | BJ29: 0 | BM29: 0 | BO29: 0 | BQ29: 29488.275 | BR29: 19858.788 | BS29: 9629.4871
A30: 2005 | B30: noviembre | D30: 12590.602 | E30: 3792.3044 | F30: 8798.298 | I30: 6850.8699 | J30: 0 | K30: 1314.803 | N30: 4609.9358 | O30: 4609.9358 | P30: 0 | Q30: 25366.211 | R30: 16567.913 | S30: 8798.298 | Y30: 0 | Z30: 835.51528 | AA30: 835.51528 | AC30: 0 | AD30: 0 | AF30: 0 | AG30: 0 | AH30: 0 | AJ30: 2173.724 | AK30: 0 | AL30: 2173.724 | AM30: 0 | AN30: 0 | AO30: 0 | AP30: 0 | AQ30: 0 | AR30: 0 | AU30: 0 | AX30: 0 | AY30: 2173.724 | AZ30: 0 | BA30: 2173.724 | BC30: 0 | BD30: 290 | BE30: 3733.4382 | BF30: 0 | BG30: 4023.4382 | BI30: 0 | BJ30: 0 | BM30: 0 | BO30: 0 | BQ30: 32398.889 | BR30: 21426.867 | BS30: 10972.022
A31: 2005 | B31: diciembre | D31: 11724.632 | E31: 2297.9396 | F31: 9426.6925 | I31: 7082.6205 | J31: 0 | K31: 992.7508 | N31: 6648.7492 | O31: 6648.7492 | P31: 0 | Q31: 26448.753 | R31: 17022.06 | S31: 9426.6925 | Y31: 0 | Z31: 1580.3357 | AA31: 1580.3357 | AC31: 0 | AD31: 0 | AF31: 0 | AG31: 0 | AH31: 0 | AJ31: 2262.01 | AK31: 0 | AL31: 2262.01 | AM31: 0 | AN31: 0 | AO31: 0 | AP31: 0 | AQ31: 0 | AR31: 0 | AU31: 0 | AX31: 0 | AY31: 2262.01 | AZ31: 0 | BA31: 2262.01 | BC31: 0 | BD31: 2588.7175 | BE31: 2563.2697 | BF31: 0 | BG31: 5151.9871 | BI31: 0 | BJ31: 0 | BM31: 0 | BO31: 0 | BQ31: 35443.085 | BR31: 23754.383 | BS31: 11688.702
... A136: 2013 | B136: total | D136: 193704.99 | E136: 37661.546 | F136: 156043.44 | I136: 463.86265 | J136: 0 | K136: 0 | N136: 36175.643 | O136: 36175.644 | P136: 0 | Q136: 230344.5 | R136: 74301.052 | S136: 156043.44 | Y136: 16898.064 | Z136: 23327.282 | AA136: 40225.346 | AC136: 2173.8321 | AD136: 2173.8321 | AF136: 15226.449 | AG136: 1349.7943 | AH136: 13876.819 | AJ136: 43791.992 | AK136: 13366.079 | AL136: 30425.913 | AM136: 0 | AN136: 0 | AO136: 0 | AP136: 1236.9673 | AQ136: 0 | AR136: 1236.9676 | AU136: 0 | AX136: 0 | AY136: 62429.24 | AZ136: 16889.706 | BA136: 45539.7 | BC136: 0 | BD136: 1917.3785 | BE136: 40608.825 | BF136: 0 | BG136: 42526.203 | BI136: 0 | BJ136: 0 | BM136: 0 | BO136: 0 | BQ136: 375525.29 | BR136: 173942.31 | BS136: 201583.14
A137: 2014 | B137: enero | C137: 0 | D137: 19268.051 | E137: 4532.6155 | F137: 14735.435 | G137: 0 | I137: 0 | J137: 0 | K137: 0 | N137: 4109.9519 | O137: 4109.9519 | P137: 0 | Q137: 23378.002 | R137: 8642.5674 | S137: 14735.435 | U137: 0 | V137: 0 | Y137: 2131.3669 | Z137: 2622.3264 | AA137: 4753.6933 | AC137: 830.62245 | AD137: 830.62245 | AE137: 0 | AF137: 1200.8093 | AG137: 0 | AH137: 1200.8093 | AI137: 0 | AJ137: 3362.0535 | AK137: 1015.9428 | AL137: 2346.1107 | AM137: 605.49878 | AN137: 605.49878 | AO137: 0 | AP137: 157.34804 | AQ137: 0 | AR137: 157.34804 | AU137: 0 | AV137: 0 | AW137: 0 | AX137: 0 | AY137: 6156.3321 | AZ137: 2452.064 | BA137: 3704.268 | BC137: 0 | BD137: 0 | BE137: 2674.2855 | BF137: 0 | BG137: 2674.2855 | BI137: 0 | BJ137: 0 | BM137: 0 | BO137: 0 | BQ137: 36962.313 | BR137: 18522.61 | BS137: 18439.703
A138: 2014 | B138: febrero | C138: 0 | D138: 19197.771 | E138: 5222.0958 | F138: 13975.675 | G138: 0 | I138: 0 | J138: 0 | K138: 0 | N138: 1129.7136 | O138: 1129.7136 | P138: 0 | Q138: 20327.484 | R138: 6351.8095 | S138: 13975.675 | U138: 0 | V138: 0 | Y138: 0 | Z138: 2287.5915 | AA138: 2287.5915 | AC138: 0 | AD138: 0 | AE138: 0 | AF138: 1225.5597 | AG138: 0 | AH138: 1225.5597 | AI138: 0 | AJ138: 5729.8858 | AK138: 2775.8796 | AL138: 2954.0062 | AM138: 0 | AN138: 0 | AO138: 0 | AP138: 0 | AQ138: 0 | AR138: 0 | AU138: 0 | AV138: 0 | AW138: 0 | AX138: 0 | AY138: 6955.4455 | AZ138: 2775.8796 | BA138: 4179.5659 | BC138: 0 | BD138: 0 | BE138: 3535.7343 | BF138: 0 | BG138: 3535.7343 | BI138: 0 | BJ138: 0 | BM138: 0 | BO138: 0 | BQ138: 33106.256 | BR138: 14951.015 | BS138: 18155.241
A139: 2014 | B139: marzo | C139: 0 | D139: 19336.771 | E139: 4772.3057 | F139: 14564.465 | G139: 0 | I139: 0 | J139: 0 | K139: 0 | N139: 2724.6155 | O139: 2724.6155 | P139: 0 | Q139: 22061.386 | R139: 7496.9212 | S139: 14564.465 | U139: 0 | V139: 0 | Y139: 2874.662 | Z139: 1272.1386 | AA139: 4146.8006 | AC139: 0 | AD139: 0 | AE139: 0 | AF139: 1309.4447 | AG139: 0 | AH139: 1309.4447 | AI139: 0 | AJ139: 3450.5752 | AK139: 948.80173 | AL139: 2501.7735 | AM139: 0 | AN139: 0 | AO139: 0 | AP139: 0 | AQ139: 0 | AR139: 0 | AU139: 0 | AV139: 0 | AW139: 0 | AX139: 0 | AY139: 4760.0199 | AZ139: 948.80173 | BA139: 3811.2181 | BC139: 0 | BD139: 0 | BE139: 2772.1875 | BF139: 0 | BG139: 2772.1875 | BI139: 0 | BJ139: 0 | BM139: 0 | BO139: 0 | BQ139: 33740.394 | BR139: 15364.711 | BS139: 18375.683
A140: 2014 | B140: abril | C140: 0 | D140: 19663.348 | E140: 7536.7148 | F140: 12126.633 | G140: 0 | I140: 0 | J140: 0 | K140: 0 | N140: 3643.7028 | O140: 3643.7028 | P140: 0 | Q140: 23307.051 | R140: 11180.418 | S140: 12126.633 | U140: 0 | V140: 0 | Y140: 837.3234 | Z140: 1717.3221 | AA140: 2554.6455 | AC140: 0 | AD140: 0 | AE140: 0 | AF140: 1327.0493 | AG140: 0 | AH140: 1327.0493 | AI140: 0 | AJ140: 3127.3877 | AK140: 967.22962 | AL140: 2160.1581 | AM140: 0 | AN140: 0 | AO140: 0 | AP140: 0 | AQ140: 0 | AR140: 0 | AU140: 0 | AV140: 0 | AW140: 0 | AX140: 0 | AY140: 4454.437 | AZ140: 967.22962 | BA140: 3487.2074 | BC140: 0 | BD140: 0 | BE140: 2715.8818 | BF140: 0 | BG140: 2715.8818 | BI140: 0 | BJ140: 0 | BM140: 0 | BO140: 0 | BQ140: 33032.015 | BR140: 17418.175 | BS140: 15613.84
A141: 2014 | B141: mayo | C141: 0 | D141: 16535.003 | E141: 4332.0366 | F141: 12202.966 | G141: 0 | I141: 0 | J141: 0 | K141: 0 | N141: 1736.8263 | O141: 1736.8263 | P141: 0 | Q141: 18271.829 | R141: 6068.8629 | S141: 12202.966 | U141: 0 | V141: 0 | Y141: 1707.3332 | Z141: 859.60534 | AA141: 2566.9385 | AC141: 463.44327 | AD141: 463.44327 | AE141: 0 | AF141: 1287.0296 | AG141: 0 | AH141: 1287.0296 | AI141: 0 | AJ141: 2753.8284 | AK141: 0 | AL141: 2753.8284 | AM141: 0 | AN141: 0 | AO141: 0 | AP141: 0 | AQ141: 0 | AR141: 0 | AU141: 0 | AV141: 0 | AW141: 0 | AX141: 0 | AY141: 4504.3013 | AZ141: 463.44327 | BA141: 4040.858 | BC141: 0 | BD141: 0 | BE141: 3204.2659 | BF141: 0 | BG141: 3204.2659 | BI141: 0 | BJ141: 0 | BM141: 0 | BO141: 0 | BQ141: 28547.335 | BR141: 12303.511 | BS141: 16243.824
A142: 2014 | B142: junio | C142: 0 | D142: 19118.348 | E142: 5974.811 | F142: 13143.537 | G142: 0 | I142: 0 | J142: 0 | K142: 0 | N142: 788.50115 | O142: 788.50115 | P142: 0 | Q142: 19906.849 | R142: 6763.3121 | S142: 13143.537 | U142: 0 | V142: 0 | Y142: 1062.8316 | Z142: 849.07026 | AA142: 1911.9018 | AC142: 0 | AD142: 0 | AE142: 0 | AF142: 1246.2605 | AG142: 0 | AH142: 1246.2605 | AI142: 0 | AJ142: 2132.1905 | AK142: 0 | AL142: 2132.1905 | AM142: 0 | AN142: 0 | AO142: 0 | AP142: 0 | AQ142: 0 | AR142: 0 | AU142: 0 | AV142: 0 | AW142: 0 | AX142: 0 | AY142: 3378.451 | AZ142: 0 | BA142: 3378.451 | BC142: 0 | BD142: 0 | BE142: 2670.7049 | BF142: 0 | BG142: 2670.7049 | BI142: 0 | BJ142: 0 | BM142: 0 | BO142: 0 | BQ142: 27867.907 | BR142: 11345.919 | BS142: 16521.988
A143: 2014 | B143: julio | C143: 0 | D143: 16667.125 | E143: 4350.624 | F143: 12316.501 | G143: 0 | I143: 0 | J143: 0 | K143: 0 | N143: 2914.3632 | O143: 2914.3632 | P143: 0 | Q143: 19581.488 | R143: 7264.9872 | S143: 12316.501 | U143: 0 | V143: 0 | Y143: 0 | Z143: 2541.3637 | AA143: 2541.3637 | AC143: 0 | AD143: 0 | AE143: 0 | AF143: 1404.4581 | AG143: 0 | AH143: 1404.4581 | AI143: 0 | AJ143: 4807.4967 | AK143: 1965.1465 | AL143: 2842.3502 | AM143: 0 | AN143: 0 | AO143: 0 | AP143: 0 | AQ143: 0 | AR143: 0 | AU143: 0 | AV143: 0 | AW143: 0 | AX143: 0 | AY143: 6211.9548 | AZ143: 1965.1465 | BA143: 4246.8084 | BC143: 0 | BD143: 0 | BE143: 2669.5613 | BF143: 0 | BG143: 2669.5613 | BI143: 0 | BJ143: 0 | BM143: 0 | BO143: 0 | BQ143: 31004.368 | BR143: 14441.059 | BS143: 16563.309
A144: 2014 | B144: agosto | C144: 0 | D144: 13064.83 | E144: 3056.3772 | F144: 10008.452 | G144: 0 | I144: 0 | J144: 0 | K144: 0 | N144: 1661.8433 | O144: 1661.8433 | P144: 0 | Q144: 14726.673 | R144: 4718.2206 | S144: 10008.452 | U144: 0 | V144: 0 | Y144: 1063.0047 | Z144: 2513.9304 | AA144: 3576.935 | AC144: 0 | AD144: 0 | AE144: 0 | AF144: 1538.2592 | AG144: 0 | AH144: 1538.2592 | AI144: 0 | AJ144: 4601.9502 | AK144: 1707.082 | AL144: 2894.8682 | AM144: 842.29657 | AN144: 842.29657 | AO144: 0 | AP144: 0 | AQ144: 0 | AR144: 0 | AU144: 0 | AV144: 0 | AW144: 0 | AX144: 0 | AY144: 6982.506 | AZ144: 2549.3785 | BA144: 4433.1274 | BC144: 0 | BD144: 0 | BE144: 2959.0978 | BF144: 0 | BG144: 2959.0978 | BI144: 0 | BJ144: 0 | BM144: 0 | BO144: 0 | BQ144: 28245.212 | BR144: 13803.632 | BS144: 14441.58
A145: 2014 | B145: septiembre | C145: 0 | D145: 17588.724 | E145: 4974.9654 | F145: 12613.759 | G145: 0 | I145: 0 | J145: 0 | K145: 0 | N145: 2745.804 | O145: 2745.804 | P145: 0 | Q145: 20334.528 | R145: 7720.7695 | S145: 12613.759 | U145: 0 | V145: 0 | Y145: 858.68251 | Z145: 2735.5212 | AA145: 3594.2037 | AC145: 0 | AD145: 0 | AE145: 0 | AF145: 1538.6718 | AG145: 0 | AH145: 1538.6718 | AI145: 0 | AJ145: 4466.8889 | AK145: 1855.8299 | AL145: 2611.059 | AM145: 0 | AN145: 0 | AO145: 0 | AP145: 0 | AQ145: 0 | AR145: 0 | AU145: 0 | AV145: 0 | AW145: 0 | AX145: 0 | AY145: 6005.5607 | AZ145: 1855.8299 | BA145: 4149.7308 | BC145: 0 | BD145: 0 | BE145: 2427.1058 | BF145: 0 | BG145: 2427.1058 | BI145: 0 | BJ145: 0 | BM145: 0 | BO145: 0 | BQ145: 32361.398 | BR145: 15597.909 | BS145: 16763.489
A146: 2014 | B146: octubre | C146: 0 | D146: 20363.79 | E146: 6567.5689 | F146: 13796.221 | G146: 0 | I146: 0 | J146: 0 | K146: 0 | N146: 4418.622 | O146: 4418.622 | P146: 0 | Q146: 24782.412 | R146: 10986.191 | S146: 13796.221 | U146: 0 | V146: 0 | Y146: 0 | Z146: 1752.8312 | AA146: 1752.8312 | AC146: 0 | AD146: 0 | AE146: 0 | AF146: 1423.8911 | AG146: 1.30259 | AH146: 1422.5885 | AI146: 0 | AJ146: 4001.0575 | AK146: 901.38406 | AL146: 3099.6734 | AM146: 0 | AN146: 0 | AO146: 0 | AP146: 0 | AQ146: 0 | AR146: 0 | AU146: 0 | AV146: 0 | AW146: 0 | AX146: 0 | AY146: 5424.9486 | AZ146: 902.68665 | BA146: 4522.2619 | BC146: 0 | BD146: 0 | BE146: 4087.8999 | BF146: 0 | BG146: 4087.8999 | BI146: 0 | BJ146: 0 | BM146: 0 | BO146: 0 | BQ146: 36048.092 | BR146: 17729.609 | BS146: 18318.483
...
